File: datafiles/CeMg3_100_MT_1kOe_SQUID_07May2012.dc.dat
[Header]
TITLE,MPMS DC Measurement
BYAPP,MPMS Measurement,2.1,Summary
FILEOPENTIME, 1336396175.953000 5/7/2012, 6:39:35 PM

INFO, APPNAME, MPMS MultiVu Application, Revision 1.56,  Build 67

INFO, NAME, CeMg3
INFO, WEIGHT, 8.000
INFO, AREA, 1.000
INFO, LENGTH, 1.000
INFO, SHAPE, bar
INFO, COMMENT, H || [100]
INFO, SEQUENCE FILE: CeSi_MT.seq


INFO, BACKGROUND DATA FILE:, None


STARTUPAXIS,X,4,LINEAR,AUTO,0.000000,0.000000
STARTUPAXIS,Y1,5,LINEAR,AUTO,0.000000,0.000000


STARTUPGROUP,Longitudinal
FIELDGROUP,Longitudinal,1,2,3,4,5,6,7,8,9,15,16,17,18,27,28
FIELDGROUP,Transverse,1,2,3,4,10,11,12,13,14,19,20,21,22,27,28

PLOT_APPEARANCE,ALL,HORZ_GRID_ON,VERT_GRID_ON,MARKERS_AND_LINES

[Data]
Time,Comment,Field (Oe),Temperature (K),Long Moment (emu),Long Scan Std Dev,Long Algorithm,Long Reg Fit,Long Percent Error (%),Trans Moment (emu),Trans Scan Std Dev,Trans Algorithm,Trans Reg Fit,Trans Percent Error (%),Long Moment [w/o ABS] (emu),Long Scan Std Dev [w/o ABS],Long Reg Fit [w/o ABS],Long Percent Error [w/o ABS] (%),Trans Moment [w/o ABS] (emu),Trans Scan Std Dev [w/o ABS],Trans Reg Fit [w/o ABS],Trans Percent Error [w/o ABS] (%),Points per Scan,Scans per Measurement,Scan Length (cm),Delta Temp (K),Rot Position (deg),Error,EC Comp. Running,Using ABS,
1336396175.953,,1.000000e+003,1.794382e+000,1.048864e-003,0.000000e+000,3,9.821061e-001,0.000000e+000,,,,,,,,,,,,,,32,1,4.000000e+000,3.399849e-004,1.500000e+001,0,,0,
1336396244.156,,1.000000e+003,1.873234e+000,1.048824e-003,0.000000e+000,3,9.820088e-001,0.000000e+000,,,,,,,,,,,,,,32,1,4.000000e+000,1.989007e-003,1.500000e+001,0,,0,
1336396410.203,,1.000000e+003,1.996731e+000,1.051267e-003,0.000000e+000,3,9.819639e-001,0.000000e+000,,,,,,,,,,,,,,32,1,4.000000e+000,9.380579e-004,1.500000e+001,0,,0,
1336396502.703,,1.000000e+003,2.107320e+000,1.052674e-003,0.000000e+000,3,9.816251e-001,0.000000e+000,,,,,,,,,,,,,,32,1,4.000000e+000,1.149893e-003,1.500000e+001,0,,0,
1336396655.578,,1.000000e+003,2.199144e+000,1.054895e-003,0.000000e+000,3,9.814369e-001,0.000000e+000,,,,,,,,,,,,,,32,1,4.000000e+000,1.474142e-003,1.500000e+001,0,,0,
1336396743.484,,1.000000e+003,2.306059e+000,1.057406e-003,0.000000e+000,3,9.814665e-001,0.000000e+000,,,,,,,,,,,,,,32,1,4.000000e+000,3.599882e-003,1.500000e+001,0,,0,
1336396828.671,,1.000000e+003,2.406041e+000,1.060092e-003,0.000000e+000,3,9.809355e-001,0.000000e+000,,,,,,,,,,,,,,32,1,4.000000e+000,3.721952e-003,1.500000e+001,0,,0,
1336396911.921,,1.000000e+003,2.506165e+000,1.064118e-003,0.000000e+000,3,9.807543e-001,0.000000e+000,,,,,,,,,,,,,,32,1,4.000000e+000,4.334927e-003,1.500000e+001,0,,0,
1336397029.609,,1.000000e+003,2.599110e+000,1.067744e-003,0.000000e+000,3,9.806498e-001,0.000000e+000,,,,,,,,,,,,,,32,1,4.000000e+000,2.835989e-003,1.500000e+001,0,,0,
1336397154.968,,1.000000e+003,2.698878e+000,1.071704e-003,0.000000e+000,3,9.805292e-001,0.000000e+000,,,,,,,,,,,,,,32,1,4.000000e+000,1.697063e-003,1.500000e+001,0,,0,
1336397283.656,,1.000000e+003,2.798564e+000,1.071433e-003,0.000000e+000,3,9.802948e-001,0.000000e+000,,,,,,,,,,,,,,32,1,4.000000e+000,1.644135e-003,1.500000e+001,0,,0,
1336397415.484,,1.000000e+003,2.898247e+000,1.060811e-003,0.000000e+000,3,9.800714e-001,0.000000e+000,,,,,,,,,,,,,,32,1,4.000000e+000,1.458168e-003,1.500000e+001,0,,0,
1336397553.375,,1.000000e+003,2.998067e+000,1.049471e-003,0.000000e+000,3,9.802588e-001,0.000000e+000,,,,,,,,,,,,,,32,1,4.000000e+000,1.405001e-003,1.500000e+001,0,,0,
1336397749.906,,1.000000e+003,3.196636e+000,1.026370e-003,0.000000e+000,3,9.801308e-001,0.000000e+000,,,,,,,,,,,,,,32,1,4.000000e+000,9.584427e-005,1.500000e+001,0,,0,
1336397979.593,,1.000000e+003,3.396270e+000,1.005065e-003,0.000000e+000,3,9.799299e-001,0.000000e+000,,,,,,,,,,,,,,32,1,4.000000e+000,3.991127e-004,1.500000e+001,0,,0,
1336398244.046,,1.000000e+003,3.596826e+000,9.846210e-004,0.000000e+000,3,9.797798e-001,0.000000e+000,,,,,,,,,,,,,,32,1,4.000000e+000,6.699562e-005,1.500000e+001,0,,0,
1336398393.312,,1.000000e+003,3.809621e+000,9.667418e-004,0.000000e+000,3,9.800203e-001,0.000000e+000,,,,,,,,,,,,,,32,1,4.000000e+000,6.210804e-004,1.500000e+001,0,,0,
1336398573.687,,1.000000e+003,4.003286e+000,9.484173e-004,0.000000e+000,3,9.798217e-001,0.000000e+000,,,,,,,,,,,,,,32,1,4.000000e+000,8.821487e-005,1.500000e+001,0,,0,
1336398783.390,,1.000000e+003,4.203523e+000,9.308957e-004,0.000000e+000,3,9.795213e-001,0.000000e+000,,,,,,,,,,,,,,32,1,4.000000e+000,5.021095e-004,1.500000e+001,0,,0,
1336399154.750,,1.000000e+003,4.390714e+000,9.158910e-004,0.000000e+000,3,9.793074e-001,0.000000e+000,,,,,,,,,,,,,,32,1,4.000000e+000,5.602837e-004,1.500000e+001,0,,0,
1336399507.453,,1.000000e+003,4.598448e+000,9.018195e-004,0.000000e+000,3,9.792748e-001,0.000000e+000,,,,,,,,,,,,,,32,1,4.000000e+000,4.143238e-003,1.500000e+001,0,,0,
1336399592.078,,1.000000e+003,4.799293e+000,8.887503e-004,0.000000e+000,3,9.792325e-001,0.000000e+000,,,,,,,,,,,,,,32,1,4.000000e+000,2.534866e-003,1.500000e+001,0,,0,
1336399676.843,,1.000000e+003,5.000299e+000,8.765443e-004,0.000000e+000,3,9.792680e-001,0.000000e+000,,,,,,,,,,,,,,32,1,4.000000e+000,2.352715e-003,1.500000e+001,0,,0,
1336399760.265,,1.000000e+003,5.200680e+000,8.653675e-004,0.000000e+000,3,9.794241e-001,0.000000e+000,,,,,,,,,,,,,,32,1,4.000000e+000,3.466129e-003,1.500000e+001,0,,0,
1336399842.671,,1.000000e+003,5.401321e+000,8.545549e-004,0.000000e+000,3,9.792922e-001,0.000000e+000,,,,,,,,,,,,,,32,1,4.000000e+000,1.712799e-003,1.500000e+001,0,,0,
1336399924.484,,1.000000e+003,5.600987e+000,8.436397e-004,0.000000e+000,3,9.791954e-001,0.000000e+000,,,,,,,,,,,,,,32,1,4.000000e+000,3.027916e-003,1.500000e+001,0,,0,
1336400005.796,,1.000000e+003,5.801282e+000,8.327967e-004,0.000000e+000,3,9.790957e-001,0.000000e+000,,,,,,,,,,,,,,32,1,4.000000e+000,3.611088e-003,1.500000e+001,0,,0,
1336400087.468,,1.000000e+003,5.998566e+000,8.225212e-004,0.000000e+000,3,9.792796e-001,0.000000e+000,,,,,,,,,,,,,,32,1,4.000000e+000,6.576061e-003,1.500000e+001,0,,0,
1336400170.796,,1.000000e+003,6.498444e+000,7.997518e-004,0.000000e+000,3,9.791107e-001,0.000000e+000,,,,,,,,,,,,,,32,1,4.000000e+000,3.825188e-003,1.500000e+001,0,,0,
1336400263.515,,1.000000e+003,6.999784e+000,7.778462e-004,0.000000e+000,3,9.788504e-001,0.000000e+000,,,,,,,,,,,,,,32,1,4.000000e+000,2.799034e-003,1.500000e+001,0,,0,
1336400355.218,,1.000000e+003,7.499948e+000,7.579725e-004,0.000000e+000,3,9.787375e-001,0.000000e+000,,,,,,,,,,,,,,32,1,4.000000e+000,3.258705e-003,1.500000e+001,0,,0,
1336400445.093,,1.000000e+003,7.995194e+000,7.392635e-004,0.000000e+000,3,9.787112e-001,0.000000e+000,,,,,,,,,,,,,,32,1,4.000000e+000,9.403229e-003,1.500000e+001,0,,0,
1336400536.609,,1.000000e+003,8.498052e+000,7.212422e-004,0.000000e+000,3,9.786121e-001,0.000000e+000,,,,,,,,,,,,,,32,1,4.000000e+000,3.499985e-003,1.500000e+001,0,,0,
1336400627.390,,1.000000e+003,8.996482e+000,7.047147e-004,0.000000e+000,3,9.784278e-001,0.000000e+000,,,,,,,,,,,,,,32,1,4.000000e+000,3.324509e-003,1.500000e+001,0,,0,
1336400719.140,,1.000000e+003,9.498964e+000,6.892217e-004,0.000000e+000,3,9.784575e-001,0.000000e+000,,,,,,,,,,,,,,32,1,4.000000e+000,2.024651e-003,1.500000e+001,0,,0,
1336400811.578,,1.000000e+003,9.995927e+000,6.744776e-004,0.000000e+000,3,9.785094e-001,0.000000e+000,,,,,,,,,,,,,,32,1,4.000000e+000,1.512527e-003,1.500000e+001,0,,0,
1336400923.640,,1.000000e+003,1.199708e+001,6.222283e-004,0.000000e+000,3,9.774784e-001,0.000000e+000,,,,,,,,,,,,,,32,1,4.000000e+000,0.000000e+000,1.500000e+001,0,,0,
1336401033.250,,1.000000e+003,1.401090e+001,5.836656e-004,0.000000e+000,3,9.780554e-001,0.000000e+000,,,,,,,,,,,,,,32,1,4.000000e+000,6.999969e-004,1.500000e+001,0,,0,
1336401138.296,,1.000000e+003,1.598321e+001,5.509534e-004,0.000000e+000,3,9.780680e-001,0.000000e+000,,,,,,,,,,,,,,32,1,4.000000e+000,5.749702e-003,1.500000e+001,0,,0,
1336401245.718,,1.000000e+003,1.798259e+001,5.227073e-004,0.000000e+000,3,9.780959e-001,0.000000e+000,,,,,,,,,,,,,,32,1,4.000000e+000,1.039886e-002,1.500000e+001,0,,0,
1336401353.750,,1.000000e+003,1.998076e+001,4.992950e-004,0.000000e+000,3,9.778990e-001,0.000000e+000,,,,,,,,,,,,,,32,1,4.000000e+000,1.099014e-002,1.500000e+001,0,,0,
1336401462.375,,1.000000e+003,2.197989e+001,4.792354e-004,0.000000e+000,3,9.781227e-001,0.000000e+000,,,,,,,,,,,,,,32,1,4.000000e+000,1.206970e-002,1.500000e+001,0,,0,
1336401574.281,,1.000000e+003,2.398092e+001,4.618520e-004,0.000000e+000,3,9.779221e-001,0.000000e+000,,,,,,,,,,,,,,32,1,4.000000e+000,5.409241e-003,1.500000e+001,0,,0,
1336401688.515,,1.000000e+003,2.600058e+001,4.467418e-004,0.000000e+000,3,9.779900e-001,0.000000e+000,,,,,,,,,,,,,,32,1,4.000000e+000,0.000000e+000,1.500000e+001,0,,0,
1336401802.984,,1.000000e+003,2.799932e+001,4.334356e-004,0.000000e+000,3,9.781577e-001,0.000000e+000,,,,,,,,,,,,,,32,1,4.000000e+000,1.399994e-003,1.500000e+001,0,,0,
1336401917.765,,1.000000e+003,2.999892e+001,4.216800e-004,0.000000e+000,3,9.781480e-001,0.000000e+000,,,,,,,,,,,,,,32,1,4.000000e+000,6.340027e-003,1.500000e+001,0,,0,
1336402086.406,,1.000000e+003,3.500149e+001,3.969489e-004,0.000000e+000,3,9.778632e-001,0.000000e+000,,,,,,,,,,,,,,32,1,4.000000e+000,2.040863e-003,1.500000e+001,0,,0,
1336402272.968,,1.000000e+003,3.999989e+001,3.780599e-004,0.000000e+000,3,9.781938e-001,0.000000e+000,,,,,,,,,,,,,,32,1,4.000000e+000,6.149292e-003,1.500000e+001,0,,0,
1336402465.296,,1.000000e+003,4.501122e+001,3.618237e-004,0.000000e+000,3,9.781070e-001,0.000000e+000,,,,,,,,,,,,,,32,1,4.000000e+000,2.490997e-003,1.500000e+001,0,,0,
1336402639.203,,1.000000e+003,5.002186e+001,3.475759e-004,0.000000e+000,3,9.777585e-001,0.000000e+000,,,,,,,,,,,,,,32,1,4.000000e+000,1.791763e-002,1.500000e+001,0,,0,
1336402811.359,,1.000000e+003,5.505944e+001,3.351800e-004,0.000000e+000,3,9.780089e-001,0.000000e+000,,,,,,,,,,,,,,32,1,4.000000e+000,1.762390e-003,1.500000e+001,0,,0,
1336402987.734,,1.000000e+003,6.007380e+001,3.235081e-004,0.000000e+000,3,9.768132e-001,0.000000e+000,,,,,,,,,,,,,,32,1,4.000000e+000,2.042007e-002,1.500000e+001,0,,0,
1336403167.781,,1.000000e+003,6.508504e+001,3.127353e-004,0.000000e+000,3,9.770383e-001,0.000000e+000,,,,,,,,,,,,,,32,1,4.000000e+000,1.644897e-002,1.500000e+001,0,,0,
1336403348.375,,1.000000e+003,7.008745e+001,3.028330e-004,0.000000e+000,3,9.778996e-001,0.000000e+000,,,,,,,,,,,,,,32,1,4.000000e+000,4.016113e-002,1.500000e+001,0,,0,
1336403531.046,,1.000000e+003,7.511785e+001,2.933305e-004,0.000000e+000,3,9.776958e-001,0.000000e+000,,,,,,,,,,,,,,32,1,4.000000e+000,1.506042e-002,1.500000e+001,0,,0,
1336403715.656,,1.000000e+003,8.014498e+001,2.842134e-004,0.000000e+000,3,9.772664e-001,0.000000e+000,,,,,,,,,,,,,,32,1,4.000000e+000,1.010132e-002,1.500000e+001,0,,0,
1336403901.718,,1.000000e+003,8.514252e+001,2.755509e-004,0.000000e+000,3,9.786832e-001,0.000000e+000,,,,,,,,,,,,,,32,1,4.000000e+000,4.866791e-002,1.500000e+001,0,,0,
1336404086.921,,1.000000e+003,9.018449e+001,2.674603e-004,0.000000e+000,3,9.764149e-001,0.000000e+000,,,,,,,,,,,,,,32,1,4.000000e+000,4.135132e-003,1.500000e+001,0,,0,
1336404273.062,,1.000000e+003,9.518881e+001,2.589050e-004,0.000000e+000,3,9.786156e-001,0.000000e+000,,,,,,,,,,,,,,32,1,4.000000e+000,9.101868e-003,1.500000e+001,0,,0,
1336404459.765,,1.000000e+003,1.002011e+002,2.517460e-004,0.000000e+000,3,9.781721e-001,0.000000e+000,,,,,,,,,,,,,,32,1,4.000000e+000,1.000214e-002,1.500000e+001,0,,0,
1336404642.906,,1.000000e+003,1.052084e+002,2.445740e-004,0.000000e+000,3,9.778728e-001,0.000000e+000,,,,,,,,,,,,,,32,1,4.000000e+000,4.370117e-002,1.500000e+001,0,,0,
1336404826.546,,1.000000e+003,1.102115e+002,2.378356e-004,0.000000e+000,3,9.777219e-001,0.000000e+000,,,,,,,,,,,,,,32,1,4.000000e+000,2.379608e-002,1.500000e+001,0,,0,
1336405026.078,,1.000000e+003,1.151859e+002,2.321098e-004,0.000000e+000,3,9.761199e-001,0.000000e+000,,,,,,,,,,,,,,32,1,4.000000e+000,4.489899e-002,1.500000e+001,0,,0,
1336405207.750,,1.000000e+003,1.202480e+002,2.273952e-004,0.000000e+000,3,9.785684e-001,0.000000e+000,,,,,,,,,,,,,,32,1,4.000000e+000,3.789520e-002,1.500000e+001,0,,0,
1336405387.687,,1.000000e+003,1.252604e+002,2.210148e-004,0.000000e+000,3,9.779738e-001,0.000000e+000,,,,,,,,,,,,,,32,1,4.000000e+000,4.800415e-002,1.500000e+001,0,,0,
1336405566.531,,1.000000e+003,1.302776e+002,2.154737e-004,0.000000e+000,3,9.782979e-001,0.000000e+000,,,,,,,,,,,,,,32,1,4.000000e+000,5.139160e-002,1.500000e+001,0,,0,
1336405744.296,,1.000000e+003,1.352942e+002,2.099412e-004,0.000000e+000,3,9.789458e-001,0.000000e+000,,,,,,,,,,,,,,32,1,4.000000e+000,3.799438e-002,1.500000e+001,0,,0,
1336405919.984,,1.000000e+003,1.403142e+002,2.052584e-004,0.000000e+000,3,9.786794e-001,0.000000e+000,,,,,,,,,,,,,,32,1,4.000000e+000,4.939270e-002,1.500000e+001,0,,0,
1336406096.343,,1.000000e+003,1.453242e+002,1.996269e-004,0.000000e+000,3,9.778880e-001,0.000000e+000,,,,,,,,,,,,,,32,1,4.000000e+000,5.740356e-002,1.500000e+001,0,,0,
1336406270.984,,1.000000e+003,1.503348e+002,1.947676e-004,0.000000e+000,3,9.778979e-001,0.000000e+000,,,,,,,,,,,,,,32,1,4.000000e+000,5.101013e-002,1.500000e+001,0,,0,
1336406445.000,,1.000000e+003,1.553438e+002,1.899192e-004,0.000000e+000,3,9.775733e-001,0.000000e+000,,,,,,,,,,,,,,32,1,4.000000e+000,6.530762e-002,1.500000e+001,0,,0,
1336406617.500,,1.000000e+003,1.603672e+002,1.851691e-004,0.000000e+000,3,9.778125e-001,0.000000e+000,,,,,,,,,,,,,,32,1,4.000000e+000,5.200195e-002,1.500000e+001,0,,0,
1336406789.046,,1.000000e+003,1.653770e+002,1.815688e-004,0.000000e+000,3,9.782605e-001,0.000000e+000,,,,,,,,,,,,,,32,1,4.000000e+000,6.118774e-002,1.500000e+001,0,,0,
1336406961.437,,1.000000e+003,1.703841e+002,1.773121e-004,0.000000e+000,3,9.783309e-001,0.000000e+000,,,,,,,,,,,,,,32,1,4.000000e+000,6.480408e-002,1.500000e+001,0,,0,
1336407131.609,,1.000000e+003,1.753910e+002,1.737790e-004,0.000000e+000,3,9.787316e-001,0.000000e+000,,,,,,,,,,,,,,32,1,4.000000e+000,8.210754e-002,1.500000e+001,0,,0,
1336407301.781,,1.000000e+003,1.804092e+002,1.695844e-004,0.000000e+000,3,9.789478e-001,0.000000e+000,,,,,,,,,,,,,,32,1,4.000000e+000,7.220459e-002,1.500000e+001,0,,0,
1336407471.218,,1.000000e+003,1.854171e+002,1.660640e-004,0.000000e+000,3,9.779156e-001,0.000000e+000,,,,,,,,,,,,,,32,1,4.000000e+000,6.838989e-002,1.500000e+001,0,,0,
1336407640.312,,1.000000e+003,1.904298e+002,1.623598e-004,0.000000e+000,3,9.785474e-001,0.000000e+000,,,,,,,,,,,,,,32,1,4.000000e+000,7.200623e-002,1.500000e+001,0,,0,
1336407808.234,,1.000000e+003,1.954359e+002,1.592745e-004,0.000000e+000,3,9.776724e-001,0.000000e+000,,,,,,,,,,,,,,32,1,4.000000e+000,7.559204e-002,1.500000e+001,0,,0,
1336407976.484,,1.000000e+003,2.004544e+002,1.558988e-004,0.000000e+000,3,9.773051e-001,0.000000e+000,,,,,,,,,,,,,,32,1,4.000000e+000,7.038879e-002,1.500000e+001,0,,0,
1336408144.343,,1.000000e+003,2.054594e+002,1.530817e-004,0.000000e+000,3,9.777780e-001,0.000000e+000,,,,,,,,,,,,,,32,1,4.000000e+000,7.380676e-002,1.500000e+001,0,,0,
1336408313.406,,1.000000e+003,2.104640e+002,1.494664e-004,0.000000e+000,3,9.767438e-001,0.000000e+000,,,,,,,,,,,,,,32,1,4.000000e+000,9.680176e-002,1.500000e+001,0,,0,
1336408479.546,,1.000000e+003,2.154741e+002,1.470530e-004,0.000000e+000,3,9.771014e-001,0.000000e+000,,,,,,,,,,,,,,32,1,4.000000e+000,1.116028e-001,1.500000e+001,0,,0,
1336408646.734,,1.000000e+003,2.204715e+002,1.438479e-004,0.000000e+000,3,9.770212e-001,0.000000e+000,,,,,,,,,,,,,,32,1,4.000000e+000,8.489990e-002,1.500000e+001,0,,0,
1336408814.687,,1.000000e+003,2.254986e+002,1.409336e-004,0.000000e+000,3,9.765504e-001,0.000000e+000,,,,,,,,,,,,,,32,1,4.000000e+000,8.880615e-002,1.500000e+001,0,,0,
1336408982.109,,1.000000e+003,2.304855e+002,1.380031e-004,0.000000e+000,3,9.765264e-001,0.000000e+000,,,,,,,,,,,,,,32,1,4.000000e+000,1.044006e-001,1.500000e+001,0,,0,
1336409151.250,,1.000000e+003,2.354906e+002,1.356134e-004,0.000000e+000,3,9.769847e-001,0.000000e+000,,,,,,,,,,,,,,32,1,4.000000e+000,7.260132e-002,1.500000e+001,0,,0,
1336409320.078,,1.000000e+003,2.404887e+002,1.326532e-004,0.000000e+000,3,9.779729e-001,0.000000e+000,,,,,,,,,,,,,,32,1,4.000000e+000,7.579041e-002,1.500000e+001,0,,0,
1336409488.421,,1.000000e+003,2.454932e+002,1.300053e-004,0.000000e+000,3,9.771394e-001,0.000000e+000,,,,,,,,,,,,,,32,1,4.000000e+000,9.880066e-002,1.500000e+001,0,,0,
1336409657.031,,1.000000e+003,2.504839e+002,1.268194e-004,0.000000e+000,3,9.753701e-001,0.000000e+000,,,,,,,,,,,,,,32,1,4.000000e+000,1.166992e-001,1.500000e+001,0,,0,
1336409825.140,,1.000000e+003,2.554846e+002,1.245864e-004,0.000000e+000,3,9.760265e-001,0.000000e+000,,,,,,,,,,,,,,32,1,4.000000e+000,9.300232e-002,1.500000e+001,0,,0,
1336409994.687,,1.000000e+003,2.604987e+002,1.213409e-004,0.000000e+000,3,9.755546e-001,0.000000e+000,,,,,,,,,,,,,,32,1,4.000000e+000,9.658813e-002,1.500000e+001,0,,0,
1336410177.343,,1.000000e+003,2.653812e+002,1.191874e-004,0.000000e+000,3,9.762065e-001,0.000000e+000,,,,,,,,,,,,,,32,1,4.000000e+000,1.157837e-001,1.500000e+001,0,,0,
1336410350.703,,1.000000e+003,2.704734e+002,1.172275e-004,0.000000e+000,3,9.775160e-001,0.000000e+000,,,,,,,,,,,,,,32,1,4.000000e+000,9.631348e-002,1.500000e+001,0,,0,
1336410520.750,,1.000000e+003,2.754966e+002,1.152000e-004,0.000000e+000,3,9.775205e-001,0.000000e+000,,,,,,,,,,,,,,32,1,4.000000e+000,7.507324e-002,1.500000e+001,0,,0,
1336410731.421,,1.000000e+003,2.801711e+002,1.126922e-004,0.000000e+000,3,9.758770e-001,0.000000e+000,,,,,,,,,,,,,,32,1,4.000000e+000,8.648682e-002,1.500000e+001,0,,0,
1336410949.937,,1.000000e+003,2.851917e+002,1.101968e-004,0.000000e+000,3,9.784600e-001,0.000000e+000,,,,,,,,,,,,,,32,1,4.000000e+000,8.059692e-002,1.500000e+001,0,,0,
1336411128.718,,1.000000e+003,2.904572e+002,1.079503e-004,0.000000e+000,3,9.767015e-001,0.000000e+000,,,,,,,,,,,,,,32,1,4.000000e+000,1.116943e-001,1.500000e+001,0,,0,
1336411342.203,,1.000000e+003,2.951982e+002,1.056562e-004,0.000000e+000,3,9.755380e-001,0.000000e+000,,,,,,,,,,,,,,32,1,4.000000e+000,5.780029e-002,1.500000e+001,0,,0,
1336411520.500,,1.000000e+003,3.004642e+002,1.030308e-004,0.000000e+000,3,9.757953e-001,0.000000e+000,,,,,,,,,,,,,,32,1,4.000000e+000,9.988403e-002,1.500000e+001,0,,0,